[2023-01-14T12:33:30.753+0000] {taskinstance.py:1087} INFO - Dependencies all met for <TaskInstance: user_processing.create_table manual__2023-01-14T12:33:24.613016+00:00 [queued]>
[2023-01-14T12:33:30.784+0000] {taskinstance.py:1087} INFO - Dependencies all met for <TaskInstance: user_processing.create_table manual__2023-01-14T12:33:24.613016+00:00 [queued]>
[2023-01-14T12:33:30.785+0000] {taskinstance.py:1283} INFO - 
--------------------------------------------------------------------------------
[2023-01-14T12:33:30.786+0000] {taskinstance.py:1284} INFO - Starting attempt 1 of 1
[2023-01-14T12:33:30.788+0000] {taskinstance.py:1285} INFO - 
--------------------------------------------------------------------------------
[2023-01-14T12:33:30.835+0000] {taskinstance.py:1304} INFO - Executing <Task(SqliteOperator): create_table> on 2023-01-14 12:33:24.613016+00:00
[2023-01-14T12:33:30.850+0000] {standard_task_runner.py:55} INFO - Started process 30771 to run task
[2023-01-14T12:33:30.867+0000] {standard_task_runner.py:82} INFO - Running: ['***', 'tasks', 'run', 'user_processing', 'create_table', 'manual__2023-01-14T12:33:24.613016+00:00', '--job-id', '20', '--raw', '--subdir', 'DAGS_FOLDER/user_processing.py', '--cfg-path', '/tmp/tmpvx72pxd7']
[2023-01-14T12:33:30.870+0000] {standard_task_runner.py:83} INFO - Job 20: Subtask create_table
[2023-01-14T12:33:31.109+0000] {task_command.py:389} INFO - Running <TaskInstance: user_processing.create_table manual__2023-01-14T12:33:24.613016+00:00 [running]> on host 35e95982c619
[2023-01-14T12:33:31.368+0000] {taskinstance.py:1513} INFO - Exporting the following env vars:
AIRFLOW_CTX_DAG_OWNER=***
AIRFLOW_CTX_DAG_ID=user_processing
AIRFLOW_CTX_TASK_ID=create_table
AIRFLOW_CTX_EXECUTION_DATE=2023-01-14T12:33:24.613016+00:00
AIRFLOW_CTX_TRY_NUMBER=1
AIRFLOW_CTX_DAG_RUN_ID=manual__2023-01-14T12:33:24.613016+00:00
[2023-01-14T12:33:31.372+0000] {sql.py:253} INFO - Executing: 
            CREATE TABLE users (
              firstname TEXT NOT NULL,
              lastname TEXT NOT NULL,
              country TEXT NOT NULL,
              username TEXT NOT NULL,
              password TEXT NOT NULL,
              email TEXT NOT NULL PRIMARY KEY
            );
            
[2023-01-14T12:33:31.400+0000] {base.py:73} INFO - Using connection ID 'db_sqlite' for task execution.
[2023-01-14T12:33:32.069+0000] {base.py:73} INFO - Using connection ID 'db_sqlite' for task execution.
[2023-01-14T12:33:32.076+0000] {sql.py:364} INFO - Running statement: 
            CREATE TABLE users (
              firstname TEXT NOT NULL,
              lastname TEXT NOT NULL,
              country TEXT NOT NULL,
              username TEXT NOT NULL,
              password TEXT NOT NULL,
              email TEXT NOT NULL PRIMARY KEY
            );
            , parameters: None
[2023-01-14T12:33:32.078+0000] {taskinstance.py:1772} ERROR - Task failed with exception
Traceback (most recent call last):
  File "/home/airflow/.local/lib/python3.7/site-packages/airflow/providers/common/sql/operators/sql.py", line 261, in execute
    return_last=self.return_last,
  File "/home/airflow/.local/lib/python3.7/site-packages/airflow/providers/common/sql/hooks/sql.py", line 338, in run
    self._run_command(cur, sql_statement, parameters)
  File "/home/airflow/.local/lib/python3.7/site-packages/airflow/providers/common/sql/hooks/sql.py", line 369, in _run_command
    cur.execute(sql_statement)
sqlite3.OperationalError: table users already exists
[2023-01-14T12:33:32.098+0000] {taskinstance.py:1327} INFO - Marking task as FAILED. dag_id=user_processing, task_id=create_table, execution_date=20230114T123324, start_date=20230114T123330, end_date=20230114T123332
[2023-01-14T12:33:32.131+0000] {standard_task_runner.py:105} ERROR - Failed to execute job 20 for task create_table (table users already exists; 30771)
[2023-01-14T12:33:32.206+0000] {local_task_job.py:159} INFO - Task exited with return code 1
[2023-01-14T12:33:32.288+0000] {taskinstance.py:2582} INFO - 0 downstream tasks scheduled from follow-on schedule check
