[2023-01-14T12:16:02.150+0000] {taskinstance.py:1087} INFO - Dependencies all met for <TaskInstance: user_processing.create_table manual__2023-01-14T12:15:58.314924+00:00 [queued]>
[2023-01-14T12:16:02.229+0000] {taskinstance.py:1087} INFO - Dependencies all met for <TaskInstance: user_processing.create_table manual__2023-01-14T12:15:58.314924+00:00 [queued]>
[2023-01-14T12:16:02.236+0000] {taskinstance.py:1283} INFO - 
--------------------------------------------------------------------------------
[2023-01-14T12:16:02.238+0000] {taskinstance.py:1284} INFO - Starting attempt 1 of 1
[2023-01-14T12:16:02.239+0000] {taskinstance.py:1285} INFO - 
--------------------------------------------------------------------------------
[2023-01-14T12:16:02.394+0000] {taskinstance.py:1304} INFO - Executing <Task(SqliteOperator): create_table> on 2023-01-14 12:15:58.314924+00:00
[2023-01-14T12:16:02.421+0000] {standard_task_runner.py:55} INFO - Started process 29970 to run task
[2023-01-14T12:16:02.436+0000] {standard_task_runner.py:82} INFO - Running: ['***', 'tasks', 'run', 'user_processing', 'create_table', 'manual__2023-01-14T12:15:58.314924+00:00', '--job-id', '14', '--raw', '--subdir', 'DAGS_FOLDER/user_processing.py', '--cfg-path', '/tmp/tmpp4vapq9m']
[2023-01-14T12:16:02.441+0000] {standard_task_runner.py:83} INFO - Job 14: Subtask create_table
[2023-01-14T12:16:02.692+0000] {task_command.py:389} INFO - Running <TaskInstance: user_processing.create_table manual__2023-01-14T12:15:58.314924+00:00 [running]> on host 35e95982c619
[2023-01-14T12:16:02.963+0000] {taskinstance.py:1513} INFO - Exporting the following env vars:
AIRFLOW_CTX_DAG_OWNER=***
AIRFLOW_CTX_DAG_ID=user_processing
AIRFLOW_CTX_TASK_ID=create_table
AIRFLOW_CTX_EXECUTION_DATE=2023-01-14T12:15:58.314924+00:00
AIRFLOW_CTX_TRY_NUMBER=1
AIRFLOW_CTX_DAG_RUN_ID=manual__2023-01-14T12:15:58.314924+00:00
[2023-01-14T12:16:02.969+0000] {sql.py:253} INFO - Executing: 
            CREATE TABLE users (
              firstname TEXT NOT NULL,
              lastname TEXT NOT NULL,
              country TEXT NOT NULL,
              username TEXT NOT NULL,
              password TEXT NOT NULL,
              email TEXT NOT NULL PRIMARY KEY
            );
            
[2023-01-14T12:16:02.999+0000] {base.py:73} INFO - Using connection ID 'db_sqlite' for task execution.
[2023-01-14T12:16:03.895+0000] {base.py:73} INFO - Using connection ID 'db_sqlite' for task execution.
[2023-01-14T12:16:03.905+0000] {sql.py:364} INFO - Running statement: 
            CREATE TABLE users (
              firstname TEXT NOT NULL,
              lastname TEXT NOT NULL,
              country TEXT NOT NULL,
              username TEXT NOT NULL,
              password TEXT NOT NULL,
              email TEXT NOT NULL PRIMARY KEY
            );
            , parameters: None
[2023-01-14T12:16:03.906+0000] {taskinstance.py:1772} ERROR - Task failed with exception
Traceback (most recent call last):
  File "/home/airflow/.local/lib/python3.7/site-packages/airflow/providers/common/sql/operators/sql.py", line 261, in execute
    return_last=self.return_last,
  File "/home/airflow/.local/lib/python3.7/site-packages/airflow/providers/common/sql/hooks/sql.py", line 338, in run
    self._run_command(cur, sql_statement, parameters)
  File "/home/airflow/.local/lib/python3.7/site-packages/airflow/providers/common/sql/hooks/sql.py", line 369, in _run_command
    cur.execute(sql_statement)
sqlite3.OperationalError: table users already exists
[2023-01-14T12:16:03.926+0000] {taskinstance.py:1327} INFO - Marking task as FAILED. dag_id=user_processing, task_id=create_table, execution_date=20230114T121558, start_date=20230114T121602, end_date=20230114T121603
[2023-01-14T12:16:03.960+0000] {standard_task_runner.py:105} ERROR - Failed to execute job 14 for task create_table (table users already exists; 29970)
[2023-01-14T12:16:03.997+0000] {local_task_job.py:159} INFO - Task exited with return code 1
[2023-01-14T12:16:04.047+0000] {taskinstance.py:2582} INFO - 0 downstream tasks scheduled from follow-on schedule check
