[2023-01-14T12:33:00.905+0000] {taskinstance.py:1087} INFO - Dependencies all met for <TaskInstance: user_processing.create_table manual__2023-01-14T12:32:57.537143+00:00 [queued]>
[2023-01-14T12:33:00.966+0000] {taskinstance.py:1087} INFO - Dependencies all met for <TaskInstance: user_processing.create_table manual__2023-01-14T12:32:57.537143+00:00 [queued]>
[2023-01-14T12:33:00.968+0000] {taskinstance.py:1283} INFO - 
--------------------------------------------------------------------------------
[2023-01-14T12:33:00.969+0000] {taskinstance.py:1284} INFO - Starting attempt 1 of 1
[2023-01-14T12:33:00.970+0000] {taskinstance.py:1285} INFO - 
--------------------------------------------------------------------------------
[2023-01-14T12:33:01.064+0000] {taskinstance.py:1304} INFO - Executing <Task(SqliteOperator): create_table> on 2023-01-14 12:32:57.537143+00:00
[2023-01-14T12:33:01.078+0000] {standard_task_runner.py:55} INFO - Started process 30742 to run task
[2023-01-14T12:33:01.090+0000] {standard_task_runner.py:82} INFO - Running: ['***', 'tasks', 'run', 'user_processing', 'create_table', 'manual__2023-01-14T12:32:57.537143+00:00', '--job-id', '17', '--raw', '--subdir', 'DAGS_FOLDER/user_processing.py', '--cfg-path', '/tmp/tmpcztacck1']
[2023-01-14T12:33:01.095+0000] {standard_task_runner.py:83} INFO - Job 17: Subtask create_table
[2023-01-14T12:33:01.523+0000] {task_command.py:389} INFO - Running <TaskInstance: user_processing.create_table manual__2023-01-14T12:32:57.537143+00:00 [running]> on host 35e95982c619
[2023-01-14T12:33:01.928+0000] {taskinstance.py:1513} INFO - Exporting the following env vars:
AIRFLOW_CTX_DAG_OWNER=***
AIRFLOW_CTX_DAG_ID=user_processing
AIRFLOW_CTX_TASK_ID=create_table
AIRFLOW_CTX_EXECUTION_DATE=2023-01-14T12:32:57.537143+00:00
AIRFLOW_CTX_TRY_NUMBER=1
AIRFLOW_CTX_DAG_RUN_ID=manual__2023-01-14T12:32:57.537143+00:00
[2023-01-14T12:33:01.930+0000] {sql.py:253} INFO - Executing: 
            CREATE TABLE users (
              firstname TEXT NOT NULL,
              lastname TEXT NOT NULL,
              country TEXT NOT NULL,
              username TEXT NOT NULL,
              password TEXT NOT NULL,
              email TEXT NOT NULL PRIMARY KEY
            );
            
[2023-01-14T12:33:01.999+0000] {base.py:73} INFO - Using connection ID 'db_sqlite' for task execution.
[2023-01-14T12:33:02.799+0000] {base.py:73} INFO - Using connection ID 'db_sqlite' for task execution.
[2023-01-14T12:33:02.808+0000] {sql.py:364} INFO - Running statement: 
            CREATE TABLE users (
              firstname TEXT NOT NULL,
              lastname TEXT NOT NULL,
              country TEXT NOT NULL,
              username TEXT NOT NULL,
              password TEXT NOT NULL,
              email TEXT NOT NULL PRIMARY KEY
            );
            , parameters: None
[2023-01-14T12:33:02.813+0000] {taskinstance.py:1772} ERROR - Task failed with exception
Traceback (most recent call last):
  File "/home/airflow/.local/lib/python3.7/site-packages/airflow/providers/common/sql/operators/sql.py", line 261, in execute
    return_last=self.return_last,
  File "/home/airflow/.local/lib/python3.7/site-packages/airflow/providers/common/sql/hooks/sql.py", line 338, in run
    self._run_command(cur, sql_statement, parameters)
  File "/home/airflow/.local/lib/python3.7/site-packages/airflow/providers/common/sql/hooks/sql.py", line 369, in _run_command
    cur.execute(sql_statement)
sqlite3.OperationalError: table users already exists
[2023-01-14T12:33:02.834+0000] {taskinstance.py:1327} INFO - Marking task as FAILED. dag_id=user_processing, task_id=create_table, execution_date=20230114T123257, start_date=20230114T123300, end_date=20230114T123302
[2023-01-14T12:33:02.869+0000] {standard_task_runner.py:105} ERROR - Failed to execute job 17 for task create_table (table users already exists; 30742)
[2023-01-14T12:33:02.925+0000] {local_task_job.py:159} INFO - Task exited with return code 1
[2023-01-14T12:33:02.984+0000] {taskinstance.py:2582} INFO - 0 downstream tasks scheduled from follow-on schedule check
